# 1 详解下下面的代码以及分析为什么

```go
package main

import (
    "fmt"
)

func test() {
    var run func() = nil
    defer run()
    fmt.Println("runs")
}

func main() {
    defer func() {
        if err := recover(); err != nil {
            fmt.Println(err)
        }
    }()
    test()
}
```

这段代码演示了 Go 语言中 `defer`、`panic` 和 `recover` 的用法，以及它们如何一起工作来处理运行时错误。这里的代码在执行时将产生一个运行时错误，但随后会被恢复（recover），程序将继续执行而不会崩溃。下面是详细的解释：

### 输出结果

代码的输出结果将是：

```
runs
runtime error: invalid memory address or nil pointer dereference
```

### 解释

1. **在 `test` 函数中**：

    - 首先，声明了一个 `run` 变量，它是一个函数类型的变量，但初始化为 `nil`，即它没有引用任何具体的函数。
    - 然后，使用 `defer run()` 注册了一个延迟调用。由于 `run` 是 `nil`，尝试调用它将在运行时引发一个 `panic`，具体错误为 "invalid memory address or nil pointer dereference"。这是因为你尝试调用了一个 `nil` 的函数指针。
    - 接着，`fmt.Println("runs")` 语句正常执行，打印 "runs"。

2. **`panic` 发生后**：

    - 程序执行到 `defer run()` 时，由于 `run` 是 `nil`，触发 `panic`。此时，Go 运行时开始寻找能够处理这个 `panic` 的 `defer` 语句。
    - 因为 `test` 函数内没有直接处理 `panic` 的 `defer` 语句，`panic` 被传递到了 `main` 函数。

3. **在 `main` 函数中**：
    - `main` 函数的开始部分通过 `defer` 注册了一个匿名函数，该函数使用 `recover` 尝试捕获并处理任何的 `panic`。
    - 当 `panic` 在 `test` 函数中发生并传播出来时，这个通过 `defer` 注册的匿名函数将被执行，`recover` 函数被调用，成功捕获 `panic`，并通过 `fmt.Println(err)` 打印出错误信息。

### 关于 `recover`

-   `recover` 是一个内建函数，用于终止一个 `panic` 的传递过程。`recover` 只有在 `defer` 函数中调用时才有效。
-   当 `recover` 捕获 `panic` 后，它会返回 `panic` 的值（如果有的话），并正常恢复程序的执行。`panic` 和 `recover` 机制类似于其他编程语言中的异常抛出和捕获。
-   如果 `defer` 中没有 `recover` 调用，或者 `defer` 函数中的 `recover` 没有被执行，`panic` 将不会被捕获，程序将终止。

### 总结

这段代码通过 `defer`、`panic` 和 `recover` 展示了 Go 语言中异常处理的一个典型例子。它演示了如何安全地处理运行时的错误，并防止因为未捕获的异常导致整个程序崩溃。这是编写健壮、可靠 Go 程序的重要技能之一。
