# 分下下这段代码以及详解下为什么

```go
package main

import "net/http"

func do() error {
    res, err := http.Get("http://www.google.com")
    defer res.Body.Close()
    if err != nil {
        return err
    }

    // ..code...

    return nil
}

func main() {
    do()
}
```

这段代码的目的是使用 Go 语言的 `http` 包发起一个 GET 请求到 "http://www.google.com"。然后，它关闭响应的 Body。这个过程中，如果发生任何错误，比如网络请求失败，它会返回那个错误。如果没有发生错误，函数会返回 `nil` 表示成功完成。

不过，这段代码存在一些问题和需要改进的地方，我们一起来分析下：

1. **`defer res.Body.Close()` 放在错误检查之前**：这个用法是不安全的。如果 `http.Get` 返回的 `err` 不为 `nil`，那么 `res` 可能会是 `nil`。这就导致了 `defer res.Body.Close()` 在尝试调用 `nil` 的 `Body` 属性的 `Close` 方法时，程序会抛出运行时错误（panic），因为你不能在一个 `nil` 的指针上调用方法。

2. **`do` 函数没有处理其返回的错误**：在 `main` 函数中调用 `do()` 时，没有对其返回的错误做任何处理。这意味着如果 `do` 函数发生了错误，程序不会有任何的错误处理逻辑来处理这个错误，可能会导致程序的行为不符合预期或者在某些情况下无法正确地通知用户错误发生了。

### 改进后的代码

为了解决这些问题，我们可以对代码进行如下改进：

```go
package main

import (
    "net/http"
)

func do() error {
    res, err := http.Get("http://www.google.com")
    if err != nil {
        return err
    }
    defer res.Body.Close() // 确保在确认 res 不为 nil 后再调用 defer

    // ..code...

    return nil
}

func main() {
    err := do()
    if err != nil {
        // 这里可以处理错误，例如打印到日志或者标准输出
        fmt.Println("Error occurred:", err)
    }
}
```

### 为什么这样改进？

-   **安全地使用 `defer`**：将 `defer res.Body.Close()` 放到了检查 `http.Get` 返回的 `err` 之后，确保了 `res` 不为 `nil` 时才调用 `defer`。这样可以避免尝试在一个 `nil` 的对象上调用方法时导致的运行时错误。
-   **错误处理**：在 `main` 函数中对 `do` 函数返回的错误进行了检查，这样可以对错误进行适当的处理，比如记录日志或者给用户反馈，从而提高程序的健壮性。
