在 Go 语言中，异常或错误通常是通过返回错误值来处理的，而不是传统的异常捕获机制。Go 语言没有 `try/catch` 块。然而，在并发编程中，特别是当使用 goroutines 时，错误处理可能需要特别的注意，因为每个 goroutine 都运行在自己的独立执行路径上。如果在 goroutine 中发生 panic（类似于其他语言的抛出异常），且没有在内部恢复（recover），那么整个程序都会崩溃。

为了安全地处理并从 goroutines 中捕获错误或异常，你可以在每个 goroutine 内部使用 `defer` 和 `recover` 函数。这允许你在 goroutine 发生 panic 时进行干预，并安全地处理这些异常情况。

### 示例：捕获和处理 goroutine 中的 panic

以下是一个如何在 goroutine 中捕获 panic 的示例：

```go
package main

import (
    "fmt"
    "time"
)

func main() {
    go safeGoroutine()
    time.Sleep(1 * time.Second)  // 等待足够时间以确保 goroutine 执行
    fmt.Println("Main function exited normally")
}

func safeGoroutine() {
    defer func() {
        if err := recover(); err != nil {
            fmt.Println("Recovered from panic:", err)
        }
    }()

    fmt.Println("safeGoroutine executed")
    causePanic()
    fmt.Println("This line will not execute")
}

func causePanic() {
    panic("something bad happened")
}
```

在这个示例中：

-   `safeGoroutine` 函数包含一个 `defer` 语句，该语句调用一个匿名函数，此函数内部使用 `recover` 来捕获和处理 panic。
-   `causePanic` 函数触发一个 panic，模拟一个异常情况。
-   当 panic 发生时，`defer` 中的 `recover` 将被调用，这防止了 panic 向上传播至 main 函数，使得主程序可以继续正常运行。

### 注意事项

1. **recover 只在 defer 调用的函数中有效**：`recover` 必须在 defer 函数中直接调用才能捕获到 panic，如果在 defer 调用的其他函数内部调用 `recover`，它是无法捕获 panic 的。
2. **goroutine 与主线程的错误处理**：主线程（或其他 goroutine）通常无法直接感知其他 goroutine 中的 panic。因此，使用像上面示例中的模式来防止 panic 影响其他部分是很有必要的。如果需要将错误状态从一个 goroutine 传递到另一个 goroutine，你应该使用通道（channel）来传递错误。

3. **设计考虑**：在设计使用 goroutines 的程序时，应考虑到错误和异常处理的策略，确保程序的健壮性。

通过这种方式，你可以更安全地使用 goroutines 来执行并行任务，同时确保异常情况能够被有效管理，不会导致整个程序崩溃。
